Workbook

Sheet README
A1: TITLE | B1: THE STOCK ELEPHANT -- Part III: Seven-Actor SFC Toy Model
A3: PURPOSE | B3: This spreadsheet implements a Stock-Flow Consistent (SFC) balance sheet model for seven actors in the international dollar circuit. Every inter-actor flow is enforced by formula. The SFC_CHECK sheet verifies that all accounting identities hold across all years.
A5: YEAR MAPPING | B5: Y0=2016 (baseline), Y1=2017, Y2=2018, Y3=2019, Y4=2020 (COVID), Y5=2021, Y6=2022 (basis trade surge), Y7=2023 (QDLP reopens), Y8=2024, Y9=2025, Y10+=Stress scenario. NOTE: In the published article, only Y0..Y10+ labels are used. No calendar dates appear in the publication.
A7: NAMING CONVENTIONS | B7: AmeriCo = reserve currency issuer (US analog). JapanCo = surplus accumulator (China analog). JapCBCo = JapanCo central bank sub-account. JapY = JapanCo domestic currency (CNY analog). JapInv = JapanCo outward investment projects (BRI analog). CommodityCo = commodity-exporting sovereign (Gulf/EM analog, generic). GlobalBankCo = large international bank. RepoCo = repo desk / FICC member. HedgeCo = basis trade vehicle (Cayman-registered). FedCo = AmeriCo central bank / absorber of last resort.
A9: UNITS | B9: All values in stylized $B (billions). Toy model -- ratios matter, not absolute scale. Real-world order-of-magnitude calibration noted in ASSUMPTIONS sheet.
A11: COLOR CODING | B11: BLUE TEXT = hardcoded input (change these for scenarios). BLACK TEXT = formula (do not hardcode). GREEN TEXT = cross-sheet reference. GREEN BACKGROUND = asset rows. ORANGE BACKGROUND = liability rows. PURPLE BACKGROUND = derivative / off-balance-sheet rows. YELLOW BACKGROUND = equity / net worth rows. BLUE BACKGROUND = fractional measure rows. RED BACKGROUND = stress scenario rows.
A13: SFC IDENTITIES | B13: The following identities must hold at every year column. They are verified in SFC_CHECK sheet. Any red cell in SFC_CHECK indicates a model error.
A14: Identity 1 | B14: JapanCo deposit at GlobalBankCo = GlobalBankCo liability to JapanCo
A15: Identity 2 | B15: CommodityCo deposit at GlobalBankCo = GlobalBankCo liability to CommodityCo
A16: Identity 3 | B16: GlobalBankCo repo to RepoCo = RepoCo repo payable to GlobalBankCo
A17: Identity 4 | B17: RepoCo repo to HedgeCo = HedgeCo repo payable to RepoCo
A18: Identity 5 | B18: HedgeCo long cash Treasury = Treasury held via repo chain (= RepoCo repo to HedgeCo)
... A28: PUBLICATION NOTE | B28: Internal working document. Publication version uses Y0..Y10+ labels only, removes CommodityCo name, removes JapCBCo/JapY/JapInv labels, and presents fractional measure formulas without estimated values. Editorial decision on what to publish made at end of drafting.
A30: PART IV EXTENSION
A31: New sheets added for Part IV -- AmeriCo Internal Sector Decomposition
A32: AmeriCo (existing) is the aggregate. Five new sheets decompose it internally.
A33: HouseholdCo | B33: Wage income, pension assets (FinServCo LPs), housing equity, consumer debt
A34: ManuCo | B34: Physical productive base -- plant, equipment, tradeable output, wage bill
A35: ProdServiceCo | B35: Technology / software / IP -- real TFP gains, equity-funded, low debt
A36: FinServCo | B36: Pension funds + insurance -- LP in HedgeCo, long-duration Treasuries, equity portfolio. FISIM income measured as GDP but not productive output.
A37: AmeriBankCo | B37: Regulated bank intermediary -- SLR-constrained, routes FedCo reserves to FinServCo via repo. The valve.
A38: GovCo | B38: Already exists. Treasury issuer, fiscal flows.
A40: INTERNAL SFC IDENTITIES (rows 12-17 in SFC_CHECK)
A41: Identity 12 | B41: ManuCo wages + ProdServiceCo wages + FinServCo wages = HouseholdCo wage income
A42: Identity 13 | B42: HouseholdCo deposits + ManuCo deposits + ProdServiceCo deposits = AmeriBankCo deposit liabilities (domestic)
A43: Identity 14 | B43: AmeriBankCo repo to FinServCo = FinServCo repo payable to AmeriBankCo
A44: Identity 15 | B44: GovCo domestic bonds = HouseholdCo pension Treasury + AmeriBankCo Treasury + FinServCo direct Treasury
A45: Identity 16 | B45: FedCo new reserves = AmeriBankCo reserve assets (each absorption episode)
A46: Identity 17 | B46: FinServCo LP stake in HedgeCo = HedgeCo equity base (ASSUMPTIONS r43)
A48: THESIS (no behavioral assumptions required)
B49: FedCo absorbs -> AmeriBankCo reserves up -> SLR routes to FinServCo repo -> discount rate falls -> ProdServiceCo equity rises (DCF identity) -> ManuCo investment crowded out (return differential) -> ManuCo wage bill shrinks -> HouseholdCo wage share falls. Every step is accounting or pricing identity.
A51: SFC INTEGRITY FIX (applied)
A52: RepoCo row 4 (Treasury asset) removed. RepoCo holds repo loan (cash claim) only. Treasury lives on HedgeCo balance sheet.
A53: Identity 18 added to SFC_CHECK: Treasury conservation. Every GovCo bond in exactly one on-balance-sheet location.
A54: Identity 18a: RepoCo on-BS Treasury = 0. Identity 18b: ClearCo on-BS Treasury = 0 (novation = memorandum only).
A55: Rule enforced: Bond ownership is unique. Repo creates claims, not duplicate assets.
A57: REVISION LOG — Reviewer fixes applied
A58: FIX 1 — Calibration triangle | B58: hedge_multiplier: 1.3→1.76 (Barth-Beltran cash/CFTC futures). novation fraction: 0.25→0.771 (TVR=22.9%).
A60: FIX 2 — κ divergence equation | B60: Explicit inequality in MEASURES: accumulation_rate vs TFP_growth. Falsification condition: κ converges only if TFP > (CA_deficit/K_real). At 7% TFP: still diverges. Part V anchor.
A62: FIX 3 — Selling sensitivity weights | B62: Seller chain now weighted simultaneous (interior solution), not purely sequential (corner solution). FS weight=0.50, AB=0.25, Official=0.25. Priority preserved, overlap allowed.
...

Sheet ASSUMPTIONS
A1: ASSUMPTIONS -- All hardcoded inputs (blue). Change here; formulas flow through.
A2: Account / Line Item | B2: Notes / Source | C2: Y0 | D2: Y1 | E2: Y2 | F2: Y3 | G2: Y4 | H2: Y5 | I2: Y6 | J2: Y7 | K2: Y8 | L2: Y9 | M2: Y10+ Stress
A3: AMERICО ASSUMPTIONS
A4: Productive capital K_real ($B) | B4: Stylized. Real-world US fixed capital ~$60T; toy model ratios matter not scale. | C4: 300 | D4: 310 | E4: 325 | F4: 340 | G4: 330 | H4: 345 | I4: 365 | J4: 380 | K4: 400 | L4: 415 | M4: 400
A5: GDP (Y_productive, $B) | B5: Toy model GDP. FISIM-adjusted -- financial sector value-add excluded. | C5: 280 | D5: 287 | E5: 294 | F5: 302 | G5: 288 | H5: 300 | I5: 308 | J5: 315 | K5: 320 | L5: 318 | M5: 300
A6: CA deficit per year ($B) | B6: Real-world US CA deficit: ~$1T/yr by 2024. Toy model scaled. | C6: 40 | D6: 45 | E6: 50 | F6: 55 | G6: 60 | H6: 65 | I6: 80 | J6: 90 | K6: 100 | L6: 110 | M6: 120
A7: NIIP Y0 starting value ($B) | B7: Only Y0 is input. Subsequent years formula: prior year + CA deficit. | C7: -80 | D7: 0 | E7: 0 | F7: 0 | G7: 0 | H7: 0 | I7: 0 | J7: 0 | K7: 0 | L7: 0 | M7: 0
A8: Official reserve liabilities Y0 ($B) | B8: Real-world: $7.5T official reserves globally. Toy model scaled. | C8: 100 | D8: 0 | E8: 0 | F8: 0 | G8: 0 | H8: 0 | I8: 0 | J8: 0 | K8: 0 | L8: 0 | M8: 0
A9: Reserve growth rate (% per year) | B9: Flat since 2015 peak. Real-world PBOC reserves ~$3.1T, stable. | C9: 0.015 | D9: 0.015 | E9: 0.01 | F9: 0.005 | G9: 0 | H9: -0.005 | I9: -0.003 | J9: 0.002 | K9: 0.005 | L9: 0.003 | M9: 0
A11: JAPANCO ASSUMPTIONS
A12: CA surplus per year ($B) | B12: SUPERSEDED by JapanCo endogenous CA = export_rev - oil_import_bill. See JapanCo trade flows rows. Two-phase Hormuz structure is now endogenous. | C12: 200 | D12: 210 | E12: 350 | F12: 420 | G12: 310 | H12: 350 | I12: 420 | J12: 250 | K12: 500 | L12: 600 | M12: 550
A13: PBOC (JapCBCo) reserve accumulation rate (% of surplus) | B13: Most surplus NOT going to official reserves since 2015. Setser routing gap. | C13: 0.05 | D13: 0.05 | E13: 0.05 | F13: 0.03 | G13: 0.02 | H13: 0.02 | I13: 0.01 | J13: 0.02 | K13: 0.01 | L13: 0.01 | M13: 0.01
A14: GlobalBankCo deposit rate (% of routing gap) | B14: State rerouting channel. BIS LBS code G proxy (loans+deposits, inseparable). | C14: 0.08 | D14: 0.09 | E14: 0.1 | F14: 0.1 | G14: 0.12 | H14: 0.13 | I14: 0.18 | J14: 0.15 | K14: 0.15 | L14: 0.14 | M14: 0.12
A15: JapInv project lending per year ($B) | B15: JapanCo outward project lending (BRI analog). | C15: 8 | D15: 10 | E15: 15 | F15: 18 | G15: 15 | H15: 15 | I15: 14 | J15: 14 | K15: 14 | L15: 12 | M15: 12
A16: Private channel open? (1=yes, 0=no) | B16: QDLP: halted Jul 2015 (pre-Y0), reinstated Apr 2018 (Y2), halted again ~Y4, QDLP expansion Sep 2023 (Y7). | C16: 0 | D16: 0 | E16: 1 | F16: 1 | G16: 0 | H16: 0 | I16: 0 | J16: 1 | K16: 1 | L16: 1 | M16: 1
A17: Private channel flow (% of surplus, if open) | B17: QDII quota: $159.7B. Small relative to total routing gap. | C17: 0 | D17: 0 | E17: 0.05 | F17: 0.05 | G17: 0 | H17: 0 | I17: 0 | J17: 0.03 | K17: 0.04 | L17: 0.05 | M17: 0.05
A19: COMMODITYCO ASSUMPTIONS
A20: Commodity receivables Y0 ($B) | B20: Oil/gas/minerals export receivables. Volatile. | C20: 60 | D20: 0 | E20: 0 | F20: 0 | G20: 0 | H20: 0 | I20: 0 | J20: 0 | K20: 0 | L20: 0 | M20: 0
A21: Commodity price change (% per year) | B21: Hormuz calibration: -70% Y10+ (largest disruption in history, 2.5% global energy supply, simultaneous with receivables collapse and import cost spike). | C21: 0.05 | D21: -0.1 | E21: 0.05 | F21: 0.1 | G21: -0.45 | H21: 0.3 | I21: 0.2 | J21: 0.05 | K21: 0.1 | L21: -0.05 | M21: -0.7
A22: GlobalBankCo deposit Y0 ($B) | B22: Dollar liquid buffer. First withdrawal target under stress. | C22: 45 | D22: 0 | E22: 0 | F22: 0 | G22: 0 | H22: 0 | I22: 0 | J22: 0 | K22: 0 | L22: 0 | M22: 0
A23: Deposit growth rate (% per year, ex-stress) | B23: Y10+ stress: CLC breach forces -45% withdrawal. | C23: 0.03 | D23: 0.04 | E23: 0.04 | F23: 0.03 | G23: -0.06 | H23: 0.08 | I23: 0.06 | J23: 0.05 | K23: 0.05 | L23: 0.02 | M23: -0.45
A24: Direct Treasury Y0 ($B) | B24: TIC-visible sovereign Treasury holdings. | C24: 20 | D24: 0 | E24: 0 | F24: 0 | G24: 0 | H24: 0 | I24: 0 | J24: 0 | K24: 0 | L24: 0 | M24: 0
A25: Treasury growth rate (% per year, ex-stress) | B25: Y10+ stress: forced sale alongside deposit withdrawal. | C25: 0.02 | D25: 0.03 | E25: 0.03 | F25: 0.02 | G25: -0.04 | H25: 0.06 | I25: 0.05 | J25: 0.04 | K25: 0.04 | L25: 0.02 | M25: -0.47
A26: Gold reserves Y0 ($B) | C26: 25 | D26: 0 | E26: 0 | F26: 0 | G26: 0 | H26: 0 | I26: 0 | J26: 0 | K26: 0 | L26: 0 | M26: 0
A27: Gold growth rate (% per year, normal)
A28: Gold liquidation fraction (stress year Y10+) | C28: 0 | D28: 0 | E28: 0 | F28: 0 | G28: 0 | H28: 0 | I28: 0 | J28: 0 | K28: 0 | L28: 0 | M28: 0.6
A29: Gold proceeds routed to GBC deposit (% of proceeds) | C29: 0 | D29: 0 | E29: 0 | F29: 0 | G29: 0 | H29: 0 | I29: 0 | J29: 0 | K29: 0 | L29: 0 | M29: 0.8
A30: GLOBALBANKCO ASSUMPTIONS
A31: Other loans and advances Y0 ($B) | C31: 25 | D31: 0 | E31: 0 | F31: 0 | G31: 0 | H31: 0 | I31: 0 | J31: 0 | K31: 0 | L31: 0 | M31: 0
A32: Other loans growth rate | C32: 0.03 | D32: 0.04 | E32: 0.04 | F32: -0.05 | G32: 0.05 | H32: 0.04 | I32: 0.04 | J32: 0.03 | K32: 0.02 | L32: -0.1 | M32: -0.15
A33: SLR minimum (%) | B33: US GSIB SLR minimum 5%. Perera (Feb 2026): SLR reform Nov 2025 changes denominator. | C33: 0.05 | D33: 0.05 | E33: 0.05 | F33: 0.05 | G33: 0.05 | H33: 0.05 | I33: 0.05 | J33: 0.05 | K33: 0.05 | L33: 0.05 | M33: 0.05
A34: SLR constraint threshold (constrained if below, %)
A35: Repo spread (GlobalBankCo to RepoCo, bps) | B35: Stylized. Repo spread widens in stress. | C35: 5 | D35: 5 | E35: 5 | F35: 5 | G35: 8 | H35: 8 | I35: 6 | J35: 6 | K35: 6 | L35: 6 | M35: 6
A37: REPOCO ASSUMPTIONS
A38: Repo spread (RepoCo to HedgeCo, bps)
A39: FICC novation fraction (% of repo book off-balance-sheet) | B39: Barth-Beltran: TVR=22.9% → novation fraction=1-0.229=0.771. TVR varies with collateral velocity and novation intensity (calibrated at 2025 Barth-Beltran vintage). | C39: 0.771 | D39: 0.3 | E39: 0.35 | F39: 0.4 | G39: 0.5 | H39: 0.55 | I39: 0.7 | J39: 0.72 | K39: 0.75 | L39: 0.76 | M39: 0.76
A41: HEDGECO ASSUMPTIONS | B41: Barth-Beltran calibration: $1.85T cash / $1.05T CFTC futures = 1.76x. Was 1.3 (uncalibrated). | C41: 1.76 | D41: 1.3 | E41: 1.3 | F41: 1.3 | G41: 1.3 | H41: 1.3 | I41: 1.3 | J41: 1.3 | K41: 1.3 | L41: 1.3 | M41: 1.3
A42: Futures short notional as multiple of cash long
A43: HedgeCo equity ($B) | B43: Equity base. Leverage = gross exposure / equity. | C43: 10 | D43: 10 | E43: 10 | F43: 10 | G43: 10 | H43: 10 | I43: 10 | J43: 10 | K43: 10 | L43: 10 | M43: 10
A45: FEDCO ASSUMPTIONS
...

Sheet REALWORLD_DATA
A1: REAL-WORLD CALIBRATION DATA | Part IV: AmeriCo Internal Sectors | 2019-2024
A2: Sources: BEA NIPA, BLS, Fed Z.1, FRED. All values are annual. Used to validate toy model stylized trajectories.
A4: Measure | B4: Toy Model Analog | C4: Source / FRED Series | D4: 2019 | E4: 2020 | F4: 2021 | G4: 2022 | H4: 2023 | I4: 2024
A5: 1. WAGE SHARE / LABOR INCOME → HouseholdCo thesis: wage share falling as FinServCo grows
A6: Wage & salary share of GDI (%) | B6: HouseholdCo wage share | C6: BEA NIPA Table 1.10 / FRED W270RE1A156NBEA | D6: 45.4 | E6: 44.6 | F6: 45.2 | G6: 44.8 | H6: 45.1 | I6: 44.9
A7: ↳ Compensation of employees (wages+salaries) as % of Gross Domestic Income. Stable but structurally below 50%. Pre-2000 was ~51-52%.
A8: Nonfarm business labor share (BLS, index 2012=100) | B8: HouseholdCo wage share | C8: BLS PRS85006173 / FRED LABSHPUSA156NRUG | D8: 98 | E8: 101.5 | F8: 100.2 | G8: 97.8 | H8: 98.5 | I8: 97.9
A9: ↳ Structural decline from ~105 in 2000. Each FedCo absorption episode sees temporary recovery then drift lower.
A10: Manufacturing compensation ($B, annual) | B10: ManuCo wage bill | C10: BEA NIPA / BLS QCEW manufacturing | D10: 920 | E10: 870 | F10: 940 | G10: 1010 | H10: 1020 | I10: 1040
A11: ↳ Real-world ~$900-1,040B. Growing nominally but shrinking as share of GDP. 2020 COVID dip then recovery driven by CHIPS Act.
A12: Finance/insurance compensation ($B, annual) | B12: FinServCo wage bill | C12: BEA GDP by Industry / FRED | D12: 510 | E12: 520 | F12: 600 | G12: 650 | H12: 680 | I12: 710
A13: ↳ Financial sector wages growing ~5-7%/yr. Faster than mfg. FISIM income expansion drives compensation growth.
A14: Info tech sector compensation ($B, annual) | B14: ProdServiceCo wage bill | C14: BEA GDP by Industry | D14: 680 | E14: 710 | F14: 820 | G14: 890 | H14: 880 | I14: 920
A15: ↳ Tech sector wages up ~35% 2019-2024. AI/cloud buildout. Positive but not sufficient to offset mfg stagnation vs FISIM growth.
A17: 2. MANUFACTURING INVESTMENT → ManuCo thesis: investment crowded out as return differential widens
A18: Mfg structures investment ($B nominal) | B18: ManuCo capital investment | C18: BEA Table 5.4.5 / FRED C307RC1A027NBEA | D18: 73 | E18: 68 | F18: 75 | G18: 104 | H18: 157 | I18: 235
A19: ↳ CHIPS Act + IRA drove surge 2022-2024. BUT: concentrated in semiconductors/batteries. Broader mfg share still falling. 2024 = $234.8B.
A20: Mfg investment / total private fixed investment (%) | B20: ManuCo investment share | C20: BEA Table 5.4.5 derived | D20: 3.4 | E20: 3.3 | F20: 3.1 | G20: 4.1 | H20: 5.4 | I20: 6.8
A21: ↳ Share rising from CHIPS/IRA but from very low base. IP/software investment (ProdServiceCo) = 31% of total vs mfg structures = 7%.
A22: IP products investment / private fixed investment (%) | B22: ProdServiceCo investment share | C22: BEA / Richmond Fed | D22: 30 | E22: 30.5 | F22: 31 | G22: 31 | H22: 31.3 | I22: 32
A23: ↳ IP (software+R&D+entertainment) = 31.3% of private fixed investment Q1 2024. Grows 3-4x faster than mfg structures.
A25: 3. TECH/FINSERV VALUATION → ProdServiceCo thesis: equity rises with FedCo discount rate suppression
A26: IT sector share of S&P 500 market cap (%) | B26: ProdServiceCo equity / GDP analog | C26: S&P Dow Jones / Bloomberg | D26: 23.2 | E26: 27.6 | F26: 28.8 | G26: 24.1 | H26: 29.5 | I26: 34
A27: ↳ IT + comm services = ~44% of S&P 500 end-2024. Rose from 33% in 2019. ~2x market cap vs 5yr avg revenue growth. Valuation re-rate driven by rate suppression.
A28: S&P 500 IT sector P/E (trailing) | B28: ProdServiceCo P/E ratio | C28: FactSet / Bloomberg | D28: 26 | E28: 40 | F28: 34 | G28: 22 | H28: 31 | I28: 33
A29: ↳ P/E compressed 2022 when Fed raised rates (22x). Expanded 2020-21 with zero rates (40x). Confirms DCF identity: FedCo rate -> ProdServiceCo valuation.
A30: Total US stock market cap / GDP (Buffett indicator, %) | B30: Financial assets / productive base | C30: Fed Z.1 / FRED | D30: 152 | E30: 195 | F30: 222 | G30: 155 | H30: 180 | I30: 201
A31: ↳ 195% peak 2020 (COVID QE). 222% 2021. Reset 2022 with rate hikes. Re-expanded 2024. Each FedCo absorption cycle visible in ratio.
A33: 4. FINANCIAL SECTOR VALUE-ADD / FISIM → FinServCo thesis: FISIM income grows without productive base expansion
A34: Finance & insurance value added / GDP (%) | B34: FinServCo FISIM share of GDP | C34: BEA GDP by Industry Table | D34: 7.5 | E34: 8.1 | F34: 8.4 | G34: 8.1 | H34: 8.3 | I34: 8.5
A35: ↳ Financial sector value added = 8.5% of GDP 2024, up from 4% in 1980. Most of growth is FISIM (imputed intermediation margin). Not productive output.
A36: Domestic financial sector total assets / GDP | B36: FinServCo balance sheet / GDP | C36: Fed Z.1 / FRED DDDI06USA156NWDB | D36: 430 | E36: 490 | F36: 510 | G36: 450 | H36: 470 | I36: 490
A37: ↳ Financial sector assets ~4.9x GDP. Each basis point of spread income on $90T+ gross financial assets = ~$90B measured GDP. Pure intermediation counted as value-add.
A39: 5. HOUSEHOLD DEBT & WEALTH DIVERGENCE → HouseholdCo thesis: nominal wealth up, real backing flat
A40: Household net worth ($T) | B40: HouseholdCo total assets | C40: Fed Z.1 Table B.101 | D40: 118.7 | E40: 130.2 | F40: 150.3 | G40: 138.4 | H40: 151 | I40: 169.4
A41: ↳ Net worth $169.4T Q4 2024 (Fed Z.1). Up 43% from 2019. Almost entirely driven by equity + housing price appreciation, not wage accumulation.
A42: Household mortgage debt ($T) | B42: HouseholdCo mortgage liabilities | C42: Fed Z.1 Table D.3 | D42: 10.7 | E42: 10.9 | F42: 11.5 | G42: 12.3 | H42: 12.8 | I42: 13.1
A43: ↳ Mortgage debt $13.1T 2024. Household debt $20.2T total Q4 2024 (Fed Z.1). Growing alongside nominal wealth but as % of wages rising.
A44: Household debt / disposable personal income (%) | B44: HouseholdCo debt / wage income | C44: Fed Z.1 / BEA | D44: 95 | E44: 97 | F44: 90 | G44: 93 | H44: 97 | I44: 99
A45: ↳ Debt burden ~97-99% of DPI. Fell briefly 2021 on stimulus income. Back to trend. Confirms HouseholdCo debt/wage rising.
...

Sheet AmeriCo
A1: AmeriCo | Reserve Issuer | Treasury Issuer | Productive Base
A2: Account / Line Item | B2: Notes / Source | C2: Y0 | D2: Y1 | E2: Y2 | F2: Y3 | G2: Y4 | H2: Y5 | I2: Y6 | J2: Y7 | K2: Y8 | L2: Y9 | M2: Y10+ Stress
A3: ASSETS
A4: Productive capital K_real ($B) | B4: FISIM-adjusted. κ divergence theorem: κ_paper rises faster than κ_real as FISIM contamination grows. | C4: =ASSUMPTIONS!C4 -> 300 | D4: =ASSUMPTIONS!D4 -> 310 | E4: =ASSUMPTIONS!E4 -> 325 | F4: =ASSUMPTIONS!F4 -> 340 | G4: =ASSUMPTIONS!G4 -> 330 | H4: =ASSUMPTIONS!H4 -> 345 | I4: =ASSUMPTIONS!I4 -> 365 | J4: =ASSUMPTIONS!J4 -> 380 | ... M4: =ASSUMPTIONS!M4 -> 400
A5: Outward FDI ($B) | B5: Channel One legacy: AmeriCo lends long via FDI while borrowing short via reserve accumulation (Kindleberger 1966). | C5: 200 | D5: =C5*(1+0.02) -> 204 | E5: =D5*(1+0.02) -> 208.08 | F5: =E5*(1+0.02) -> 212.2416 | G5: =F5*(1+0.02) -> 216.48643 | H5: =G5*(1+0.02) -> 220.81616 | I5: =H5*(1+0.02) -> 225.23248 | J5: =I5*(1+0.02) -> 229.73713 | K5: =J5*(1+0.02) -> 234.33188 | ... M5: =L5*(1+0.02) -> 243.79888
A6: Other foreign claims ($B) | C6: 80 | D6: =C6*1.02 -> 81.6 | E6: =D6*1.02 -> 83.232 | F6: =E6*1.02 -> 84.89664 | G6: =F6*1.02 -> 86.594573 | H6: =G6*1.02 -> 88.326464 | I6: =H6*1.02 -> 90.092994 | J6: =I6*1.02 -> 91.894853 | K6: =J6*1.02 -> 93.73275 | ... M6: =L6*1.02 -> 97.519554
A7: TOTAL ASSETS | C7: =SUM(C4:C6) -> 580 | D7: =SUM(D4:D6) -> 595.6 | E7: =SUM(E4:E6) -> 616.312 | F7: =SUM(F4:F6) -> 637.13824 | G7: =SUM(G4:G6) -> 633.081 | H7: =SUM(H4:H6) -> 654.14262 | I7: =SUM(I4:I6) -> 680.32548 | J7: =SUM(J4:J6) -> 701.63199 | ... M7: =SUM(M4:M6) -> 741.31844
A9: LIABILITIES
A10: Official reserve liabilities ($B) [SELLER 3: sold after FinServCo + AmeriBankCo exhausted] | B10: Foreign CB holdings. Third seller in chain. Drains after HC_delta > 90B (FinServCo 60 + AmeriBankCo 30 exhausted). Represents reserve drawdown. | C10: =MAX(0,100-MIN(100,MAX(0,(HedgeCo!C4-ASSUMPTIONS!C70)*ASSUMPTIONS!C86*4))) -> 100 | D10: =MAX(0,100-MIN(100,MAX(0,(HedgeCo!D4-ASSUMPTIONS!C70)*ASSUMPTIONS!C86*4))) -> 75.445 | E10: =MAX(0,100-MIN(100,MAX(0,(HedgeCo!E4-ASSUMPTIONS!C70)*ASSUMPTIONS!C86*4))) -> 34.0497 | F10: =MAX(0,100-MIN(100,MAX(0,(HedgeCo!F4-ASSUMPTIONS!C70)*ASSUMPTIONS!C86*4))) -> 0 | G10: =MAX(0,100-MIN(100,MAX(0,(HedgeCo!G4-ASSUMPTIONS!C70)*ASSUMPTIONS!C86*4))) -> 0 | H10: =MAX(0,100-MIN(100,MAX(0,(HedgeCo!H4-ASSUMPTIONS!C70)*ASSUMPTIONS!C86*4))) -> 0 | I10: =MAX(0,100-MIN(100,MAX(0,(HedgeCo!I4-ASSUMPTIONS!C70)*ASSUMPTIONS!C86*4))) -> 0 | J10: =MAX(0,100-MIN(100,MAX(0,(HedgeCo!J4-ASSUMPTIONS!C70)*ASSUMPTIONS!C86*4))) -> 0 | K10: =MAX(0,100-MIN(100,MAX(0,(HedgeCo!K4-ASSUMPTIONS!C70)*ASSUMPTIONS!C86*4))) -> 0 | L10: =MAX(0,100-MIN(100,MAX(0,(HedgeCo!L4-ASSUMPTIONS!C70)*ASSUMPTIONS!C86*4))) -> 0 | M10: =MAX(0,100-MIN(100,MAX(0,(HedgeCo!M4-ASSUMPTIONS!C70)*ASSUMPTIONS!C86*4))) -> 0
A11: Private foreign Treasury (TIC-visible, $B) | B11: Barth-Beltran TIC-visible portion: $423B end-Y8. TVR = this / total basis trade. | C11: =RepoCo!C4 -> 0 | D11: =RepoCo!D4 -> 0 | E11: =RepoCo!E4 -> 0 | F11: =RepoCo!F4 -> 0 | G11: =RepoCo!G4 -> 0 | H11: =RepoCo!H4 -> 0 | I11: =RepoCo!I4 -> 0 | J11: =RepoCo!J4 -> 0 | ... M11: =RepoCo!M4 -> 0
A12: Private foreign Treasury (TIC-INVISIBLE, $B) | B12: Basis trade exposure invisible via FICC novation. Barth-Beltran: $1,427B invisible end-Y8. | C12: =RepoCo!C13 -> 61.68 | D12: =RepoCo!D13 -> 31.3665 | E12: =RepoCo!E13 -> 51.082605 | F12: =RepoCo!F13 -> 78.762991 | G12: =RepoCo!G13 -> 121.085 | H12: =RepoCo!H13 -> 167.78307 | I12: =RepoCo!I13 -> 306.50803 | J12: =RepoCo!J13 -> 413.02591 | ... M12: =RepoCo!M13 -> 777.16258
A13: Other foreign dollar claims ($B) | C13: 200 | D13: =C13*1.02 -> 204 | E13: =D13*1.02 -> 208.08 | F13: =E13*1.02 -> 212.2416 | G13: =F13*1.02 -> 216.48643 | H13: =G13*1.02 -> 220.81616 | I13: =H13*1.02 -> 225.23248 | J13: =I13*1.02 -> 229.73713 | K13: =J13*1.02 -> 234.33188 | ... M13: =L13*1.02 -> 243.79888
A14: TOTAL LIABILITIES | C14: =SUM(C10:C13) -> 361.68 | D14: =SUM(D10:D13) -> 310.8115 | E14: =SUM(E10:E13) -> 293.21231 | F14: =SUM(F10:F13) -> 291.00459 | G14: =SUM(G10:G13) -> 337.57143 | H14: =SUM(H10:H13) -> 388.59924 | I14: =SUM(I10:I13) -> 531.74051 | J14: =SUM(J10:J13) -> 642.76304 | ... M14: =SUM(M10:M13) -> 1020.9615
A16: NET INTERNATIONAL INVESTMENT POSITION (NIIP)
A17: NIIP = Total Assets - Total Liabilities ($B) | B17: Real-world: US NIIP = -$26.5T end-2024. Toy model scaled ratios. | C17: =C7-C14 -> 218.32 | D17: =D7-D14 -> 284.7885 | E17: =E7-E14 -> 323.09969 | F17: =F7-F14 -> 346.13365 | G17: =G7-G14 -> 295.50957 | H17: =H7-H14 -> 265.54339 | I17: =I7-I14 -> 148.58497 | J17: =J7-J14 -> 58.868945 | ... M17: =M7-M14 -> -279.64303
A19: FLOWS
A20: CA deficit per year ($B) | B20: Each year's deficit = net new claims issued on AmeriCo. Stock accumulates without ceiling. | C20: =ASSUMPTIONS!C7 -> -80 | D20: =ASSUMPTIONS!D7 -> 0 | E20: =ASSUMPTIONS!E7 -> 0 | F20: =ASSUMPTIONS!F7 -> 0 | G20: =ASSUMPTIONS!G7 -> 0 | H20: =ASSUMPTIONS!H7 -> 0 | I20: =ASSUMPTIONS!I7 -> 0 | J20: =ASSUMPTIONS!J7 -> 0 | ... M20: =ASSUMPTIONS!M7 -> 0
A22: FRACTIONAL MEASURES
A23: κ_paper = K_total / Y_productive | B23: Rising. FISIM contamination means κ_real diverges lower. Core κ divergence theorem claim. | C23: =(C7-C11-C12)/ASSUMPTIONS!C5 -> 1.8511429 | D23: =(D7-D11-D12)/ASSUMPTIONS!D5 -> 1.9659704 | E23: =(E7-E11-E12)/ASSUMPTIONS!E5 -> 1.922549 | F23: =(F7-F11-F12)/ASSUMPTIONS!F5 -> 1.8489247 | G23: =(G7-G11-G12)/ASSUMPTIONS!G5 -> 1.7777639 | H23: =(H7-H11-H12)/ASSUMPTIONS!H5 -> 1.6211985 | I23: =(I7-I11-I12)/ASSUMPTIONS!I5 -> 1.213693 | J23: =(J7-J11-J12)/ASSUMPTIONS!J5 -> 0.91620977 | ... M23: =(M7-M11-M12)/ASSUMPTIONS!M5 -> -0.11948048
A24: NIIP / GDP | B24: Interest burden at 4%: ~$300B/yr on official reserves alone by Y8. | C24: =C17/ASSUMPTIONS!C5 -> 0.77971429 | D24: =D17/ASSUMPTIONS!D5 -> 0.99229443 | E24: =E17/ASSUMPTIONS!E5 -> 1.0989786 | F24: =F17/ASSUMPTIONS!F5 -> 1.1461379 | G24: =G17/ASSUMPTIONS!G5 -> 1.0260749 | H24: =H17/ASSUMPTIONS!H5 -> 0.88514463 | I24: =I17/ASSUMPTIONS!I5 -> 0.48241872 | J24: =J17/ASSUMPTIONS!J5 -> 0.18688554 | ... M24: =M17/ASSUMPTIONS!M5 -> -0.93214343
A25: TVR = TIC-visible / (TIC-visible + TIC-invisible) | B25: Barth-Beltran: TVR = $423B / $1,850B = 22.9% end-Y8. Structural gauge failure. | C25: =IF((C11+C12)=0,"-",C11/(C11+C12)) -> 0 | D25: =IF((D11+D12)=0,"-",D11/(D11+D12)) -> 0 | E25: =IF((E11+E12)=0,"-",E11/(E11+E12)) -> 0 | F25: =IF((F11+F12)=0,"-",F11/(F11+F12)) -> 0 | G25: =IF((G11+G12)=0,"-",G11/(G11+G12)) -> 0 | H25: =IF((H11+H12)=0,"-",H11/(H11+H12)) -> 0 | I25: =IF((I11+I12)=0,"-",I11/(I11+I12)) -> 0 | J25: =IF((J11+J12)=0,"-",J11/(J11+J12)) -> 0 | ... M25: =IF((M11+M12)=0,"-",M11/(M11+M12)) -> 0

Sheet GovCo
A1: GovCo | AmeriCo Treasury & Finance Ministry | Sovereign Debt Issuer
A2: Account / Line Item | B2: Notes | C2: Y0 | D2: Y1 | E2: Y2 | F2: Y3 | G2: Y4 | H2: Y5 | I2: Y6 | J2: Y7 | K2: Y8 | L2: Y9 | M2: Y10+
A3: ASSETS
A4: GovCo financial assets / cash ($B) [stock: Y0=20, decremented by fiscal deficit] | B4: Stock of liquid government assets. Y0 stylized. Depleted by annual fiscal deficit. | C4: 20 | D4: =MAX(0,C4-C19) -> 0 | E4: =MAX(0,D4-D19) -> 0 | F4: =MAX(0,E4-E19) -> 0 | G4: =MAX(0,F4-F19) -> 0 | H4: =MAX(0,G4-G19) -> 0 | I4: =MAX(0,H4-H19) -> 0 | J4: =MAX(0,I4-I19) -> 0 | K4: =MAX(0,J4-J19) -> 0 | ... M4: =MAX(0,L4-L19) -> 0
A5: Other government assets ($B) | B5: Reserves, land, enterprise stakes | C5: 80 | D5: 80 | E5: 80 | F5: 80 | G5: 80 | H5: 80 | I5: 80 | J5: 80 | K5: 80 | L5: 80 | M5: 80
A6: TOTAL ASSETS | C6: =SUM(C4:C5) -> 100 | D6: =SUM(D4:D5) -> 80 | E6: =SUM(E4:E5) -> 80 | F6: =SUM(F4:F5) -> 80 | G6: =SUM(G4:G5) -> 80 | H6: =SUM(H4:H5) -> 80 | I6: =SUM(I4:I5) -> 80 | J6: =SUM(J4:J5) -> 80 | ... M6: =SUM(M4:M5) -> 80
A8: LIABILITIES
A9: GovCo bonds held by FedCo ($B) [SFC: = FedCo Treasury holdings] | B9: FedCo!Treasury r4 | C9: =FedCo!C4 -> 64 | D9: =FedCo!D4 -> 79 | E9: =FedCo!E4 -> 94 | F9: =FedCo!F4 -> 114 | G9: =FedCo!G4 -> 194 | H9: =FedCo!H4 -> 186 | I9: =FedCo!I4 -> 166 | J9: =FedCo!J4 -> 141 | ... M9: =FedCo!M4 -> 163
A10: Foreign private holdings via basis trade (HedgeCo cash TSY, $B) [SFC: = HedgeCo!cash_treasury] | B10: HedgeCo is the bond HOLDER. GlobalBankCo is only the financier (repo). Ownership and financing are distinct. SFC: = HedgeCo row 4. | C10: =HedgeCo!C4 -> 80 | D10: =HedgeCo!D4 -> 104.555 | E10: =HedgeCo!E4 -> 145.9503 | F10: =HedgeCo!F4 -> 196.90748 | G10: =HedgeCo!G4 -> 242.17 | H10: =HedgeCo!H4 -> 305.06014 | I10: =HedgeCo!I4 -> 437.86861 | J10: =HedgeCo!J4 -> 573.64709 | ... M10: =HedgeCo!M4 -> 1022.5823
A11: Official reserve liabilities ($B) [= AmeriCo r10 = foreign central bank Treasury holdings] | B11: AmeriCo official reserve liabilities (foreign CB holdings) | C11: =AmeriCo!C10 -> 100 | D11: =AmeriCo!D10 -> 75.445 | E11: =AmeriCo!E10 -> 34.0497 | F11: =AmeriCo!F10 -> 0 | G11: =AmeriCo!G10 -> 0 | H11: =AmeriCo!H10 -> 0 | I11: =AmeriCo!I10 -> 0 | J11: =AmeriCo!J10 -> 0 | ... M11: =AmeriCo!M10 -> 0
A12: Domestic: HouseholdCo direct TSY ($B) [= HouseholdCo!direct_treasury] | B12: Retail T-bills, MMF, savings bonds. 15% of GovCo total. SFC: = HouseholdCo!r8. | C12: =HouseholdCo!C8 -> #VALUE! | D12: =HouseholdCo!D8 -> #VALUE! | E12: =HouseholdCo!E8 -> #VALUE! | F12: =HouseholdCo!F8 -> #VALUE! | G12: =HouseholdCo!G8 -> #VALUE! | H12: =HouseholdCo!H8 -> #VALUE! | I12: =HouseholdCo!I8 -> #VALUE! | J12: =HouseholdCo!J8 -> #VALUE! | ... M12: =HouseholdCo!M8 -> #VALUE!
A13: Domestic: InsuranceCo TSY ($B) [= InsuranceCo!TSY_portfolio] | B13: Life insurance + DB pensions (ex-FinServCo LP chain). 12% of GovCo total. | C13: =InsuranceCo!C5 -> #VALUE! | D13: =InsuranceCo!D5 -> #VALUE! | E13: =InsuranceCo!E5 -> #VALUE! | F13: =InsuranceCo!F5 -> #VALUE! | G13: =InsuranceCo!G5 -> #VALUE! | H13: =InsuranceCo!H5 -> #VALUE! | I13: =InsuranceCo!I5 -> #VALUE! | J13: =InsuranceCo!J5 -> #VALUE! | ... M13: =InsuranceCo!M5 -> #VALUE!
A14: FinServCo long-duration TSY ($B) [= FinServCo!r5] | B14: FinServCo pension/insurance TSY portfolio. Shrinks as HedgeCo scales (seller chain). SFC mirror. | C14: =FinServCo!C5 -> 60 | D14: =FinServCo!D5 -> 35.445 | E14: =FinServCo!E5 -> 0 | F14: =FinServCo!F5 -> 0 | G14: =FinServCo!G5 -> 0 | H14: =FinServCo!H5 -> 0 | I14: =FinServCo!I5 -> 0 | J14: =FinServCo!J5 -> 0 | ... M14: =FinServCo!M5 -> 0
A15: AmeriBankCo HQLA Treasury ($B) [= AmeriBankCo!r6] | B15: AmeriBankCo LCR/HQLA Treasury holdings. Shrinks in reallocation chain (seller 2). SFC mirror. | C15: =AmeriBankCo!C6 -> 30 | D15: =AmeriBankCo!D6 -> 5.445 | E15: =AmeriBankCo!E6 -> 0 | F15: =AmeriBankCo!F6 -> 0 | G15: =AmeriBankCo!G6 -> 0 | H15: =AmeriBankCo!H6 -> 0 | I15: =AmeriBankCo!I6 -> 0 | J15: =AmeriBankCo!J6 -> 0 | ... M15: =AmeriBankCo!M6 -> 0
A16: OtherBankCo TSY ($B) [RESIDUAL ABSORBER: GovCo total − all 7 named holders] | B16: Y0=0B. Absorbs new GovCo issuance not taken by other named holders. True swing buyer. | C16: =GovCo!C18-GovCo!C9-GovCo!C10-GovCo!C11-GovCo!C12-GovCo!C13-GovCo!C14-GovCo!C15 -> #VALUE! | D16: =GovCo!D18-GovCo!D9-GovCo!D10-GovCo!D11-GovCo!D12-GovCo!D13-GovCo!D14-GovCo!D15 -> #VALUE! | E16: =GovCo!E18-GovCo!E9-GovCo!E10-GovCo!E11-GovCo!E12-GovCo!E13-GovCo!E14-GovCo!E15 -> #VALUE! | F16: =GovCo!F18-GovCo!F9-GovCo!F10-GovCo!F11-GovCo!F12-GovCo!F13-GovCo!F14-GovCo!F15 -> #VALUE! | G16: =GovCo!G18-GovCo!G9-GovCo!G10-GovCo!G11-GovCo!G12-GovCo!G13-GovCo!G14-GovCo!G15 -> #VALUE! | H16: =GovCo!H18-GovCo!H9-GovCo!H10-GovCo!H11-GovCo!H12-GovCo!H13-GovCo!H14-GovCo!H15 -> #VALUE! | I16: =GovCo!I18-GovCo!I9-GovCo!I10-GovCo!I11-GovCo!I12-GovCo!I13-GovCo!I14-GovCo!I15 -> #VALUE! | J16: =GovCo!J18-GovCo!J9-GovCo!J10-GovCo!J11-GovCo!J12-GovCo!J13-GovCo!J14-GovCo!J15 -> #VALUE! | ... M16: =GovCo!M18-GovCo!M9-GovCo!M10-GovCo!M11-GovCo!M12-GovCo!M13-GovCo!M14-GovCo!M15 -> #VALUE!
A17: True residual (= 0 by construction — OtherBankCo absorbs remainder) | B17: GovCo total - all 8 named holders. Must be zero. If non-zero: OtherBankCo formula error. | C17: =C18-C9-C10-C11-C12-C13-C14-C15-C16 -> #VALUE! | D17: =D18-D9-D10-D11-D12-D13-D14-D15-D16 -> #VALUE! | E17: =E18-E9-E10-E11-E12-E13-E14-E15-E16 -> #VALUE! | F17: =F18-F9-F10-F11-F12-F13-F14-F15-F16 -> #VALUE! | G17: =G18-G9-G10-G11-G12-G13-G14-G15-G16 -> #VALUE! | H17: =H18-H9-H10-H11-H12-H13-H14-H15-H16 -> #VALUE! | I17: =I18-I9-I10-I11-I12-I13-I14-I15-I16 -> #VALUE! | J17: =J18-J9-J10-J11-J12-J13-J14-J15-J16 -> #VALUE! | ... M17: =M18-M9-M10-M11-M12-M13-M14-M15-M16 -> #VALUE!
A18: TOTAL LIABILITIES (GovCo bonds outstanding, $B) | B18: Grows via fiscal deficit each year. The whole governs the parts. | C18: =ASSUMPTIONS!C52 -> 380 | D18: =MAX(0,C18+C21) -> #VALUE! | E18: =MAX(0,D18+D21) -> #VALUE! | F18: =MAX(0,E18+E21) -> #VALUE! | G18: =MAX(0,F18+F21) -> #VALUE! | H18: =MAX(0,G18+G21) -> #VALUE! | I18: =MAX(0,H18+H21) -> #VALUE! | J18: =MAX(0,I18+I21) -> #VALUE! | K18: =MAX(0,J18+J21) -> #VALUE! | ... M18: =MAX(0,L18+L21) -> #VALUE!
A19: Government spending ($B) | C19: =ASSUMPTIONS!C56 -> 300 | D19: =ASSUMPTIONS!D56 -> 300 | E19: =ASSUMPTIONS!E56 -> 300 | F19: =ASSUMPTIONS!F56 -> 300 | G19: =ASSUMPTIONS!G56 -> 300 | H19: =ASSUMPTIONS!H56 -> 300 | I19: =ASSUMPTIONS!I56 -> 300 | J19: =ASSUMPTIONS!J56 -> 300 | ... M19: =ASSUMPTIONS!M56 -> 300
A20: Interest on outstanding bonds ($B) | B20: Rate times total bonds outstanding prior year | C20: =ASSUMPTIONS!C54*ASSUMPTIONS!C52 -> 15.2 | D20: =ASSUMPTIONS!D54*C13 -> #VALUE! | E20: =ASSUMPTIONS!E54*D13 -> #VALUE! | F20: =ASSUMPTIONS!F54*E13 -> #VALUE! | G20: =ASSUMPTIONS!G54*F13 -> #VALUE! | H20: =ASSUMPTIONS!H54*G13 -> #VALUE! | I20: =ASSUMPTIONS!I54*H13 -> #VALUE! | J20: =ASSUMPTIONS!J54*I13 -> #VALUE! | K20: =ASSUMPTIONS!K54*J13 -> #VALUE! | ... M20: =ASSUMPTIONS!M54*L13 -> #VALUE!
A21: Fiscal deficit ($B) = spending + interest - revenue | C21: =C17+C18-C16 -> #VALUE! | D21: =D17+D18-D16 -> #VALUE! | E21: =E17+E18-E16 -> #VALUE! | F21: =F17+F18-F16 -> #VALUE! | G21: =G17+G18-G16 -> #VALUE! | H21: =H17+H18-H16 -> #VALUE! | I21: =I17+I18-I16 -> #VALUE! | J21: =J17+J18-J16 -> #VALUE! | ... M21: =M17+M18-M16 -> #VALUE!
A23: FRACTIONAL MEASURES
A24: Debt / GDP | C24: =IF(ASSUMPTIONS!C5=0,"-",C13/ASSUMPTIONS!C5) -> #VALUE! | D24: =IF(ASSUMPTIONS!C5=0,"-",D13/ASSUMPTIONS!C5) -> #VALUE! | E24: =IF(ASSUMPTIONS!C5=0,"-",E13/ASSUMPTIONS!C5) -> #VALUE! | F24: =IF(ASSUMPTIONS!C5=0,"-",F13/ASSUMPTIONS!C5) -> #VALUE! | G24: =IF(ASSUMPTIONS!C5=0,"-",G13/ASSUMPTIONS!C5) -> #VALUE! | H24: =IF(ASSUMPTIONS!C5=0,"-",H13/ASSUMPTIONS!C5) -> #VALUE! | I24: =IF(ASSUMPTIONS!C5=0,"-",I13/ASSUMPTIONS!C5) -> #VALUE! | J24: =IF(ASSUMPTIONS!C5=0,"-",J13/ASSUMPTIONS!C5) -> #VALUE! | K24: =IF(ASSUMPTIONS!C5=0,"-",K13/ASSUMPTIONS!C5) -> #VALUE! | L24: =IF(ASSUMPTIONS!C5=0,"-",L13/ASSUMPTIONS!C5) -> #VALUE! | M24: =IF(ASSUMPTIONS!C5=0,"-",M13/ASSUMPTIONS!C5) -> #VALUE!
A25: Foreign-held share of GovCo bonds (visible + invisible) | C25: =IF(C13=0,"-",(C10+C11)/C13) -> #VALUE! | D25: =IF(D13=0,"-",(D10+D11)/D13) -> #VALUE! | E25: =IF(E13=0,"-",(E10+E11)/E13) -> #VALUE! | F25: =IF(F13=0,"-",(F10+F11)/F13) -> #VALUE! | G25: =IF(G13=0,"-",(G10+G11)/G13) -> #VALUE! | H25: =IF(H13=0,"-",(H10+H11)/H13) -> #VALUE! | I25: =IF(I13=0,"-",(I10+I11)/I13) -> #VALUE! | J25: =IF(J13=0,"-",(J10+J11)/J13) -> #VALUE! | ... M25: =IF(M13=0,"-",(M10+M11)/M13) -> #VALUE!
A26: FedCo-held share of GovCo bonds | C26: =IF(C13=0,"-",C9/C13) -> #VALUE! | D26: =IF(D13=0,"-",D9/D13) -> #VALUE! | E26: =IF(E13=0,"-",E9/E13) -> #VALUE! | F26: =IF(F13=0,"-",F9/F13) -> #VALUE! | G26: =IF(G13=0,"-",G9/G13) -> #VALUE! | H26: =IF(H13=0,"-",H9/H13) -> #VALUE! | I26: =IF(I13=0,"-",I9/I13) -> #VALUE! | J26: =IF(J13=0,"-",J9/J13) -> #VALUE! | ... M26: =IF(M13=0,"-",M9/M13) -> #VALUE!
A27: Interest burden / tax revenue (debt service ratio) | C27: =IF(C16=0,"-",C18/C16) -> #VALUE! | D27: =IF(D16=0,"-",D18/D16) -> #VALUE! | E27: =IF(E16=0,"-",E18/E16) -> #VALUE! | F27: =IF(F16=0,"-",F18/F16) -> #VALUE! | G27: =IF(G16=0,"-",G18/G16) -> #VALUE! | H27: =IF(H16=0,"-",H18/H16) -> #VALUE! | I27: =IF(I16=0,"-",I18/I16) -> #VALUE! | J27: =IF(J16=0,"-",J18/J16) -> #VALUE! | ... M27: =IF(M16=0,"-",M18/M16) -> #VALUE!
A28: TIC-invisible / foreign private chain (reporting gap -- ClearCo novated / total repo) | B28: Rising = structural reporting gap widening | C28: =IF(GlobalBankCo!C4=0,"-",ClearCo!C4/GlobalBankCo!C4) -> 0.771 | D28: =IF(GlobalBankCo!D4=0,"-",ClearCo!D4/GlobalBankCo!D4) -> 0.3 | E28: =IF(GlobalBankCo!E4=0,"-",ClearCo!E4/GlobalBankCo!E4) -> 0.35 | F28: =IF(GlobalBankCo!F4=0,"-",ClearCo!F4/GlobalBankCo!F4) -> 0.4 | G28: =IF(GlobalBankCo!G4=0,"-",ClearCo!G4/GlobalBankCo!G4) -> 0.5 | H28: =IF(GlobalBankCo!H4=0,"-",ClearCo!H4/GlobalBankCo!H4) -> 0.55 | I28: =IF(GlobalBankCo!I4=0,"-",ClearCo!I4/GlobalBankCo!I4) -> 0.7 | J28: =IF(GlobalBankCo!J4=0,"-",ClearCo!J4/GlobalBankCo!J4) -> 0.72 | ... M28: =IF(GlobalBankCo!M4=0,"-",ClearCo!M4/GlobalBankCo!M4) -> 0.76
A30: Effective bond supply for basis trade (= new issuance × duration mix) | B30: When yield exceeds 5.5% threshold, GovCo shifts to bills. Effective bond collateral = fiscal_deficit × MEASURES!duration_mix. Bills do not serve as basis trade collateral. | C30: =GovCo!C21*MEASURES!C47 -> #VALUE! | D30: =GovCo!D21*MEASURES!D47 -> #VALUE! | E30: =GovCo!E21*MEASURES!E47 -> #VALUE! | F30: =GovCo!F21*MEASURES!F47 -> #VALUE! | G30: =GovCo!G21*MEASURES!G47 -> #VALUE! | H30: =GovCo!H21*MEASURES!H47 -> #VALUE! | I30: =GovCo!I21*MEASURES!I47 -> #VALUE! | J30: =GovCo!J21*MEASURES!J47 -> #VALUE! | ... M30: =GovCo!M21*MEASURES!M47 -> #VALUE!

Sheet HouseholdCo
A1: HouseholdCo | Wage Earners + Asset Holders | Dual Exposure
A2: Wage income from ManuCo+ProdServiceCo+FinServCo. Pension assets in FinServCo (LP channel). Nominal wealth rising via asset prices; real productive backing flat. Wage share falling.
A3: Account / Line Item | B3: Notes / Source | C3: Y0 | D3: Y1 | E3: Y2 | F3: Y3 | G3: Y4 | H3: Y5 | I3: Y6 | J3: Y7 | K3: Y8 | L3: Y9 | M3: Y10+ Stress
A4: ASSETS
A5: Pension assets — claim on FinServCo net worth ($B) [SFC: FinServCo assets − obligations] | B5: HH holds FinServCo NET worth, not gross. = FinServCo total assets - pension obligations - repo payable. | C5: =FinServCo!C9-FinServCo!C11-FinServCo!C12 -> -35 | D5: =FinServCo!D9-FinServCo!D11-FinServCo!D12 -> -36 | E5: =FinServCo!E9-FinServCo!E11-FinServCo!E12 -> -36.92 | F5: =FinServCo!F9-FinServCo!F11-FinServCo!F12 -> -38.9104 | G5: =FinServCo!G9-FinServCo!G11-FinServCo!G12 -> -39.135168 | H5: =FinServCo!H9-FinServCo!H11-FinServCo!H12 -> -40.534092 | I5: =FinServCo!I9-FinServCo!I11-FinServCo!I12 -> -42.288864 | J5: =FinServCo!J9-FinServCo!J11-FinServCo!J12 -> -42.590639 | ... M5: =FinServCo!M9-FinServCo!M11-FinServCo!M12 -> -47.797553
A6: Housing equity ($B) | B6: Real asset. Sensitive to interest rates (mortgage cost = FedCo rate). Rises with suppressed rates. | C6: 80 | D6: 84 | E6: 88 | F6: 94 | G6: 90 | H6: 100 | I6: 110 | J6: 115 | K6: 120 | L6: 122 | M6: 108
A7: Deposits at AmeriBankCo ($B) [SFC: Identity 13 partial] | B7: Checking + savings. SFC: HouseholdCo deposit = AmeriBankCo deposit liability (domestic HH portion). | C7: =ASSUMPTIONS!C5*0.25 -> 70 | D7: =ASSUMPTIONS!D5*0.25 -> 71.75 | E7: =ASSUMPTIONS!E5*0.25 -> 73.5 | F7: =ASSUMPTIONS!F5*0.25 -> 75.5 | G7: =ASSUMPTIONS!G5*0.25 -> 72 | H7: =ASSUMPTIONS!H5*0.25 -> 75 | I7: =ASSUMPTIONS!I5*0.25 -> 77 | J7: =ASSUMPTIONS!J5*0.25 -> 78.75 | ... M7: =ASSUMPTIONS!M5*0.25 -> 75
A8: Direct Treasury holdings ($B) [SFC: GovCo holder HH_direct] | B8: Y0=45.0B (11.8% of GovCo). Grows proportionally with new GovCo issuance. | C8: =28*(GovCo!C16/ASSUMPTIONS!C52) -> #VALUE! | D8: =28*(GovCo!D16/ASSUMPTIONS!C52) -> #VALUE! | E8: =28*(GovCo!E16/ASSUMPTIONS!C52) -> #VALUE! | F8: =28*(GovCo!F16/ASSUMPTIONS!C52) -> #VALUE! | G8: =28*(GovCo!G16/ASSUMPTIONS!C52) -> #VALUE! | H8: =28*(GovCo!H16/ASSUMPTIONS!C52) -> #VALUE! | I8: =28*(GovCo!I16/ASSUMPTIONS!C52) -> #VALUE! | J8: =28*(GovCo!J16/ASSUMPTIONS!C52) -> #VALUE! | K8: =28*(GovCo!K16/ASSUMPTIONS!C52) -> #VALUE! | L8: =28*(GovCo!L16/ASSUMPTIONS!C52) -> #VALUE! | M8: =28*(GovCo!M16/ASSUMPTIONS!C52) -> #VALUE!
A9: TOTAL ASSETS | C9: =SUM(C5:C8) -> #VALUE! | D9: =SUM(D5:D8) -> #VALUE! | E9: =SUM(E5:E8) -> #VALUE! | F9: =SUM(F5:F8) -> #VALUE! | G9: =SUM(G5:G8) -> #VALUE! | H9: =SUM(H5:H8) -> #VALUE! | I9: =SUM(I5:I8) -> #VALUE! | J9: =SUM(J5:J8) -> #VALUE! | ... M9: =SUM(M5:M8) -> #VALUE!
A10: LIABILITIES
A11: Mortgage debt ($B) | B11: Sensitive to rates. Cheaper when FedCo suppresses. Housing equity inflated by same suppression. | C11: 60 | D11: 62 | E11: 64 | F11: 67 | G11: 65 | H11: 68 | I11: 72 | J11: 74 | K11: 76 | L11: 78 | M11: 80
A12: Consumer + student debt ($B) | B12: Rising. Real wages flat -> more debt to maintain consumption. | C12: 25 | D12: 26 | E12: 27 | F12: 28 | G12: 28 | H12: 29 | I12: 30 | J12: 31 | K12: 32 | L12: 33 | M12: 34
A13: TOTAL LIABILITIES | C13: =SUM(C11:C12) -> 85 | D13: =SUM(D11:D12) -> 88 | E13: =SUM(E11:E12) -> 91 | F13: =SUM(F11:F12) -> 95 | G13: =SUM(G11:G12) -> 93 | H13: =SUM(H11:H12) -> 97 | I13: =SUM(I11:I12) -> 102 | J13: =SUM(J11:J12) -> 105 | ... M13: =SUM(M11:M12) -> 114
A14: NET WORTH = Total Assets − Total Liabilities | B14: HH net worth. Rises nominally via asset price inflation. Flat in real terms if wage share falls. | C14: =C9-C13 -> #VALUE! | D14: =D9-D13 -> #VALUE! | E14: =E9-E13 -> #VALUE! | F14: =F9-F13 -> #VALUE! | G14: =G9-G13 -> #VALUE! | H14: =H9-H13 -> #VALUE! | I14: =I9-I13 -> #VALUE! | J14: =J9-J13 -> #VALUE! | ... M14: =M9-M13 -> #VALUE!
A15: Wage income from ManuCo ($B) [SFC: = ManuCo!wage_bill] | B15: ManuCo wage bill. Declining. ASSUMPTIONS row 59. | C15: =ManuCo!C12 -> 80 | D15: =ManuCo!D12 -> 79 | E15: =ManuCo!E12 -> 78 | F15: =ManuCo!F12 -> 77 | G15: =ManuCo!G12 -> 70 | H15: =ManuCo!H12 -> 72 | I15: =ManuCo!I12 -> 73 | J15: =ManuCo!J12 -> 72 | ... M15: =ManuCo!M12 -> 65
A16: Wage income from ProdServiceCo ($B) [SFC: = ProdServiceCo!wage_bill] | B16: ProdServiceCo wage bill. Growing. ASSUMPTIONS row 61. | C16: =ProdServiceCo!C12 -> 60 | D16: =ProdServiceCo!D12 -> 63 | E16: =ProdServiceCo!E12 -> 67 | F16: =ProdServiceCo!F12 -> 72 | G16: =ProdServiceCo!G12 -> 68 | H16: =ProdServiceCo!H12 -> 78 | I16: =ProdServiceCo!I12 -> 88 | J16: =ProdServiceCo!J12 -> 96 | ... M16: =ProdServiceCo!M12 -> 108
A17: Wage income from FinServCo ($B) [SFC: = FinServCo!wage_bill] | B17: FinServCo wage bill. Growing with FISIM. ASSUMPTIONS row 63. | C17: =FinServCo!C15 -> 105 | D17: =FinServCo!D15 -> 111 | E17: =FinServCo!E15 -> 118.71 | F17: =FinServCo!F15 -> 128.2468 | G17: =FinServCo!G15 -> 148.5585 | H17: =FinServCo!H15 -> 169.8702 | I17: =FinServCo!I15 -> 190.65073 | J17: =FinServCo!J15 -> 206.2158 | ... M17: =FinServCo!M15 -> 251.55703
A18: TOTAL WAGE INCOME ($B) [SFC Identity 12 total] | B18: Sum of all three. SFC: must = ManuCo + ProdServiceCo + FinServCo wage bills. | C18: =SUM(C15:C17) -> 245 | D18: =SUM(D15:D17) -> 253 | E18: =SUM(E15:E17) -> 263.71 | F18: =SUM(F15:F17) -> 277.2468 | G18: =SUM(G15:G17) -> 286.5585 | H18: =SUM(H15:H17) -> 319.8702 | I18: =SUM(I15:I17) -> 351.65073 | J18: =SUM(J15:J17) -> 374.2158 | ... M18: =SUM(M15:M17) -> 424.55703
A19: FRACTIONAL MEASURES
A20: Wage share of GDP (total HouseholdCo wages / GDP) | B20: CORE THESIS MEASURE. Falling as FinServCo grows relative to ManuCo. FedCo absorptions do not expand wage base. | C20: =IF(ASSUMPTIONS!C5=0,"-",C18/ASSUMPTIONS!C5) -> 0.875 | D20: =IF(ASSUMPTIONS!D5=0,"-",D18/ASSUMPTIONS!D5) -> 0.8815331 | E20: =IF(ASSUMPTIONS!E5=0,"-",E18/ASSUMPTIONS!E5) -> 0.89697279 | F20: =IF(ASSUMPTIONS!F5=0,"-",F18/ASSUMPTIONS!F5) -> 0.91803576 | G20: =IF(ASSUMPTIONS!G5=0,"-",G18/ASSUMPTIONS!G5) -> 0.99499479 | H20: =IF(ASSUMPTIONS!H5=0,"-",H18/ASSUMPTIONS!H5) -> 1.066234 | I20: =IF(ASSUMPTIONS!I5=0,"-",I18/ASSUMPTIONS!I5) -> 1.1417231 | J20: =IF(ASSUMPTIONS!J5=0,"-",J18/ASSUMPTIONS!J5) -> 1.1879867 | ... M20: =IF(ASSUMPTIONS!M5=0,"-",M18/ASSUMPTIONS!M5) -> 1.4151901
A21: ManuCo wage share of total wages | B21: Declining. The picker's share of household income falling. | C21: =IF(C18=0,"-",C15/C18) -> 0.32653061 | D21: =IF(D18=0,"-",D15/D18) -> 0.31225296 | E21: =IF(E18=0,"-",E15/E18) -> 0.29577945 | F21: =IF(F18=0,"-",F15/F18) -> 0.27773089 | G21: =IF(G18=0,"-",G15/G18) -> 0.24427822 | H21: =IF(H18=0,"-",H15/H18) -> 0.2250913 | I21: =IF(I18=0,"-",I15/I18) -> 0.20759235 | J21: =IF(J18=0,"-",J15/J18) -> 0.19240235 | ... M21: =IF(M18=0,"-",M15/M18) -> 0.15310075
A22: Nominal wealth / wage income ratio | B22: Rising. Asset price inflation outpaces wage growth. Wealth looks fine. Income pressure growing. | C22: =IF(C18=0,"-",C9/C18) -> #VALUE! | D22: =IF(D18=0,"-",D9/D18) -> #VALUE! | E22: =IF(E18=0,"-",E9/E18) -> #VALUE! | F22: =IF(F18=0,"-",F9/F18) -> #VALUE! | G22: =IF(G18=0,"-",G9/G18) -> #VALUE! | H22: =IF(H18=0,"-",H9/H18) -> #VALUE! | I22: =IF(I18=0,"-",I9/I18) -> #VALUE! | J22: =IF(J18=0,"-",J9/J18) -> #VALUE! | ... M22: =IF(M18=0,"-",M9/M18) -> #VALUE!
A23: Debt / wage income | B23: Rising. Debt serviced from wages. As wage share falls, debt burden rises. | C23: =IF(C18=0,"-",C13/C18) -> 0.34693878 | D23: =IF(D18=0,"-",D13/D18) -> 0.34782609 | E23: =IF(E18=0,"-",E13/E18) -> 0.34507603 | F23: =IF(F18=0,"-",F13/F18) -> 0.34265499 | G23: =IF(G18=0,"-",G13/G18) -> 0.32454106 | H23: =IF(H18=0,"-",H13/H18) -> 0.303248 | I23: =IF(I18=0,"-",I13/I18) -> 0.29006054 | J23: =IF(J18=0,"-",J13/J18) -> 0.28058676 | ... M23: =IF(M18=0,"-",M13/M18) -> 0.26851516

Sheet ManuCo
A1: ManuCo | Physical Productive Base | The Orange Picker
A2: Plant, equipment, tradeable output. Wage bill = primary HouseholdCo income source. Investment crowded out as return differential widens vs FinServCo.
A3: Account / Line Item | B3: Notes / Source | C3: Y0 | D3: Y1 | E3: Y2 | F3: Y3 | G3: Y4 | H3: Y5 | I3: Y6 | J3: Y7 | K3: Y8 | L3: Y9 | M3: Y10+ Stress
A4: ASSETS
A5: Physical capital stock ($B) | B5: ManuCo share of AmeriCo K_real. Declining as investment routes to ProdServiceCo/FinServCo. | C5: 195 | D5: 198.4 | E5: 204.8 | F5: 210.8 | G5: 198 | H5: 203.5 | I5: 208 | J5: 209 | K5: 212 | L5: 211.7 | M5: 200
A6: Trade receivables ($B) | B6: Export earnings. Tradeable goods output. | C6: 15 | D6: 16 | E6: 16 | F6: 17 | G6: 14 | H6: 16 | I6: 17 | J6: 17 | K6: 18 | L6: 18 | M6: 16
A7: TOTAL ASSETS | C7: =SUM(C5:C6) -> 210 | D7: =SUM(D5:D6) -> 214.4 | E7: =SUM(E5:E6) -> 220.8 | F7: =SUM(F5:F6) -> 227.8 | G7: =SUM(G5:G6) -> 212 | H7: =SUM(H5:H6) -> 219.5 | I7: =SUM(I5:I6) -> 225 | J7: =SUM(J5:J6) -> 226 | ... M7: =SUM(M5:M6) -> 216
A8: LIABILITIES
A9: Corporate debt ($B) | B9: Equipment financing, working capital. Real-world: US mfg debt load rising. | C9: 40 | D9: 42 | E9: 44 | F9: 46 | G9: 44 | H9: 46 | I9: 48 | J9: 49 | K9: 50 | L9: 51 | M9: 52
A10: TOTAL LIABILITIES | C10: =C9 -> 40 | D10: =D9 -> 42 | E10: =E9 -> 44 | F10: =F9 -> 46 | G10: =G9 -> 44 | H10: =H9 -> 46 | I10: =I9 -> 48 | J10: =J9 -> 49 | ... M10: =M9 -> 52
A11: INCOME FLOWS
A12: Wage bill ($B) [SFC: = HouseholdCo!manu_wages] | B12: From ASSUMPTIONS row 59. Declining. SFC: must equal HouseholdCo manu wage income. | C12: =ASSUMPTIONS!C59 -> 80 | D12: =ASSUMPTIONS!D59 -> 79 | E12: =ASSUMPTIONS!E59 -> 78 | F12: =ASSUMPTIONS!F59 -> 77 | G12: =ASSUMPTIONS!G59 -> 70 | H12: =ASSUMPTIONS!H59 -> 72 | I12: =ASSUMPTIONS!I59 -> 73 | J12: =ASSUMPTIONS!J59 -> 72 | ... M12: =ASSUMPTIONS!M59 -> 65
A13: Capital investment ($B) | B13: ManuCo capex. = GDP * investment share. Declining as return differential routes capital to FinServCo. | C13: =ASSUMPTIONS!C5*ASSUMPTIONS!C65 -> 28 | D13: =ASSUMPTIONS!D5*ASSUMPTIONS!D65 -> 28.126 | E13: =ASSUMPTIONS!E5*ASSUMPTIONS!E65 -> 28.224 | F13: =ASSUMPTIONS!F5*ASSUMPTIONS!F65 -> 28.388 | G13: =ASSUMPTIONS!G5*ASSUMPTIONS!G65 -> 24.48 | H13: =ASSUMPTIONS!H5*ASSUMPTIONS!H65 -> 26.4 | I13: =ASSUMPTIONS!I5*ASSUMPTIONS!I65 -> 26.488 | J13: =ASSUMPTIONS!J5*ASSUMPTIONS!J65 -> 26.46 | ... M13: =ASSUMPTIONS!M5*ASSUMPTIONS!M65 -> 22.5
A14: Output / revenue ($B) | B14: Productive output. FISIM-clean -- no financial spread income. | C14: 110 | D14: 113 | E14: 116 | F14: 120 | G14: 102 | H14: 112 | I14: 118 | J14: 122 | K14: 126 | L14: 128 | M14: 118
A15: FRACTIONAL MEASURES
A16: Wage bill / GDP (wage share, ManuCo) | B16: Declining. Core thesis: FedCo absorption episodes do not expand ManuCo wage base. | C16: =IF(ASSUMPTIONS!C5=0,"-",C12/ASSUMPTIONS!C5) -> 0.28571429 | D16: =IF(ASSUMPTIONS!D5=0,"-",D12/ASSUMPTIONS!D5) -> 0.27526132 | E16: =IF(ASSUMPTIONS!E5=0,"-",E12/ASSUMPTIONS!E5) -> 0.26530612 | F16: =IF(ASSUMPTIONS!F5=0,"-",F12/ASSUMPTIONS!F5) -> 0.25496689 | G16: =IF(ASSUMPTIONS!G5=0,"-",G12/ASSUMPTIONS!G5) -> 0.24305556 | H16: =IF(ASSUMPTIONS!H5=0,"-",H12/ASSUMPTIONS!H5) -> 0.24 | I16: =IF(ASSUMPTIONS!I5=0,"-",I12/ASSUMPTIONS!I5) -> 0.23701299 | J16: =IF(ASSUMPTIONS!J5=0,"-",J12/ASSUMPTIONS!J5) -> 0.22857143 | ... M16: =IF(ASSUMPTIONS!M5=0,"-",M12/ASSUMPTIONS!M5) -> 0.21666667
A17: Capital investment / GDP | B17: ManuCo investment share. Structural decline = picker aging. | C17: =ASSUMPTIONS!C65 -> 0.1 | D17: =ASSUMPTIONS!D65 -> 0.098 | E17: =ASSUMPTIONS!E65 -> 0.096 | F17: =ASSUMPTIONS!F65 -> 0.094 | G17: =ASSUMPTIONS!G65 -> 0.085 | H17: =ASSUMPTIONS!H65 -> 0.088 | I17: =ASSUMPTIONS!I65 -> 0.086 | J17: =ASSUMPTIONS!J65 -> 0.084 | ... M17: =ASSUMPTIONS!M65 -> 0.075
A18: Return on capital (output / capital stock) | B18: Falling IRR. At high kappa, return to productive investment < return to financial intermediation. | C18: =IF(C5=0,"-",C14/C5) -> 0.56410256 | D18: =IF(D5=0,"-",D14/D5) -> 0.56955645 | E18: =IF(E5=0,"-",E14/E5) -> 0.56640625 | F18: =IF(F5=0,"-",F14/F5) -> 0.56925996 | G18: =IF(G5=0,"-",G14/G5) -> 0.51515152 | H18: =IF(H5=0,"-",H14/H5) -> 0.55036855 | I18: =IF(I5=0,"-",I14/I5) -> 0.56730769 | J18: =IF(J5=0,"-",J14/J5) -> 0.58373206 | ... M18: =IF(M5=0,"-",M14/M5) -> 0.59
A20: EQUITY & RETAINED EARNINGS
A21: Retained earnings ($B) = output − wages − debt interest | B21: Capital income after wages and debt service. Reinvested or distributed. | C21: =C14-C12-(C9*0.04) -> 28.4 | D21: =D14-D12-(D9*0.04) -> 32.32 | E21: =E14-E12-(E9*0.04) -> 36.24 | F21: =F14-F12-(F9*0.04) -> 41.16 | G21: =G14-G12-(G9*0.04) -> 30.24 | H21: =H14-H12-(H9*0.04) -> 38.16 | I21: =I14-I12-(I9*0.04) -> 43.08 | J21: =J14-J12-(J9*0.04) -> 48.04 | ... M21: =M14-M12-(M9*0.04) -> 50.92
A22: Net worth = Capital stock − Corporate debt + Retained earnings | B22: ManuCo equity. Declining as IRR falls and retained earnings compress. | C22: =C5-C9+C21 -> 183.4 | D22: =D5-D9+D21 -> 188.72 | E22: =E5-E9+E21 -> 197.04 | F22: =F5-F9+F21 -> 205.96 | G22: =G5-G9+G21 -> 184.24 | H22: =H5-H9+H21 -> 195.66 | I22: =I5-I9+I21 -> 203.08 | J22: =J5-J9+J21 -> 208.04 | ... M22: =M5-M9+M21 -> 198.92

Sheet ProdServiceCo
A1: ProdServiceCo | Technology & Software | Real TFP Gains
A2: IP, software, AI infrastructure. Equity-funded. Valuation rises mechanically as FedCo suppresses discount rate. TFP gains real but racing against κ accumulation.
A3: Account / Line Item | B3: Notes / Source | C3: Y0 | D3: Y1 | E3: Y2 | F3: Y3 | G3: Y4 | H3: Y5 | I3: Y6 | J3: Y7 | K3: Y8 | L3: Y9 | M3: Y10+ Stress
A4: ASSETS
A5: IP & software capital stock ($B) | B5: ProdServiceCo share of AmeriCo K_real. Growing. | C5: 60 | D5: 65.1 | E5: 71.5 | F5: 78.2 | G5: 75.9 | H5: 82.8 | I5: 94.9 | J5: 106.4 | K5: 120 | L5: 132.8 | M5: 128
A6: Equity market valuation ($B) | B6: annual output × P/E ratio (ASSUMPTIONS row 66). Rises as FedCo absorbs and discount rate falls. | C6: =C14*ASSUMPTIONS!C66 -> 1210 | D6: =D14*ASSUMPTIONS!D66 -> 1416 | E6: =E14*ASSUMPTIONS!E66 -> 1664 | F6: =F14*ASSUMPTIONS!F66 -> 1960 | G6: =G14*ASSUMPTIONS!G66 -> 1560 | H6: =H14*ASSUMPTIONS!H66 -> 2730 | I6: =I14*ASSUMPTIONS!I66 -> 3420 | J6: =J14*ASSUMPTIONS!J66 -> 3168 | ... M6: =M14*ASSUMPTIONS!M66 -> 1980
A7: TOTAL ASSETS (book) | C7: =SUM(C5:C5) -> 60 | D7: =SUM(D5:D5) -> 65.1 | E7: =SUM(E5:E5) -> 71.5 | F7: =SUM(F5:F5) -> 78.2 | G7: =SUM(G5:G5) -> 75.9 | H7: =SUM(H5:H5) -> 82.8 | I7: =SUM(I5:I5) -> 94.9 | J7: =SUM(J5:J5) -> 106.4 | ... M7: =SUM(M5:M5) -> 128
A8: LIABILITIES
A9: Equity held by investors ($B) [SFC: FinServCo equity portfolio + HH direct equity] | B9: Wired to actual holders. FinServCo pension equity portfolio + HH direct equity (fraction of HH net worth). | C9: =FinServCo!C6+HouseholdCo!C14*ASSUMPTIONS!C71 -> #VALUE! | D9: =FinServCo!D6+HouseholdCo!D14*ASSUMPTIONS!C71 -> #VALUE! | E9: =FinServCo!E6+HouseholdCo!E14*ASSUMPTIONS!C71 -> #VALUE! | F9: =FinServCo!F6+HouseholdCo!F14*ASSUMPTIONS!C71 -> #VALUE! | G9: =FinServCo!G6+HouseholdCo!G14*ASSUMPTIONS!C71 -> #VALUE! | H9: =FinServCo!H6+HouseholdCo!H14*ASSUMPTIONS!C71 -> #VALUE! | I9: =FinServCo!I6+HouseholdCo!I14*ASSUMPTIONS!C71 -> #VALUE! | J9: =FinServCo!J6+HouseholdCo!J14*ASSUMPTIONS!C71 -> #VALUE! | K9: =FinServCo!K6+HouseholdCo!K14*ASSUMPTIONS!C71 -> #VALUE! | L9: =FinServCo!L6+HouseholdCo!L14*ASSUMPTIONS!C71 -> #VALUE! | M9: =FinServCo!M6+HouseholdCo!M14*ASSUMPTIONS!C71 -> #VALUE!
A10: Private credit debt to FinServCo ($B) [SFC ID27: = FinServCo!PC_loans] | B10: Mirror of FinServCo PC loan. Exact equality enforced by SFC Identity 27. | C10: =FinServCo!C9 -> 20 | D10: =FinServCo!D9 -> 22 | E10: =FinServCo!E9 -> 25.08 | F10: =FinServCo!F9 -> 28.0896 | G10: =FinServCo!G9 -> 32.864832 | H10: =FinServCo!H9 -> 37.465908 | I10: =FinServCo!I9 -> 42.711136 | J10: =FinServCo!J9 -> 47.409361 | ... M10: =FinServCo!M9 -> 52.202447
A11: TOTAL LIABILITIES | B11: External equity + PC debt. | C11: =SUM(C9:C10) -> #VALUE! | D11: =SUM(D9:D10) -> #VALUE! | E11: =SUM(E9:E10) -> #VALUE! | F11: =SUM(F9:F10) -> #VALUE! | G11: =SUM(G9:G10) -> #VALUE! | H11: =SUM(H9:H10) -> #VALUE! | I11: =SUM(I9:I10) -> #VALUE! | J11: =SUM(J9:J10) -> #VALUE! | ... M11: =SUM(M9:M10) -> #VALUE!
A12: Wage bill ($B) [SFC: = HouseholdCo!prod_wages] | B12: From ASSUMPTIONS row 61. Growing. | C12: =ASSUMPTIONS!C61 -> 60 | D12: =ASSUMPTIONS!D61 -> 63 | E12: =ASSUMPTIONS!E61 -> 67 | F12: =ASSUMPTIONS!F61 -> 72 | G12: =ASSUMPTIONS!G61 -> 68 | H12: =ASSUMPTIONS!H61 -> 78 | I12: =ASSUMPTIONS!I61 -> 88 | J12: =ASSUMPTIONS!J61 -> 96 | ... M12: =ASSUMPTIONS!M61 -> 108
A13: Capital investment ($B) | B13: R&D + software + AI capex. Equity-funded. Grows independently of FedCo cycle. | C13: =C5*0.12 -> 7.2 | D13: =D5*0.12 -> 7.812 | E13: =E5*0.12 -> 8.58 | F13: =F5*0.12 -> 9.384 | G13: =G5*0.12 -> 9.108 | H13: =H5*0.12 -> 9.936 | I13: =I5*0.12 -> 11.388 | J13: =J5*0.12 -> 12.768 | ... M13: =M5*0.12 -> 15.36
A14: Output / revenue ($B) | B14: Technology services, software. FISIM-clean. | C14: 55 | D14: 59 | E14: 64 | F14: 70 | G14: 65 | H14: 78 | I14: 90 | J14: 99 | K14: 110 | L14: 118 | M14: 110
A15: FRACTIONAL MEASURES
A16: Wage bill / GDP | B16: Growing. ProdServiceCo expanding wage share. But: does it offset ManuCo decline? Key empirical question. | C16: =IF(ASSUMPTIONS!C5=0,"-",C12/ASSUMPTIONS!C5) -> 0.21428571 | D16: =IF(ASSUMPTIONS!D5=0,"-",D12/ASSUMPTIONS!D5) -> 0.2195122 | E16: =IF(ASSUMPTIONS!E5=0,"-",E12/ASSUMPTIONS!E5) -> 0.22789116 | F16: =IF(ASSUMPTIONS!F5=0,"-",F12/ASSUMPTIONS!F5) -> 0.2384106 | G16: =IF(ASSUMPTIONS!G5=0,"-",G12/ASSUMPTIONS!G5) -> 0.23611111 | H16: =IF(ASSUMPTIONS!H5=0,"-",H12/ASSUMPTIONS!H5) -> 0.26 | I16: =IF(ASSUMPTIONS!I5=0,"-",I12/ASSUMPTIONS!I5) -> 0.28571429 | J16: =IF(ASSUMPTIONS!J5=0,"-",J12/ASSUMPTIONS!J5) -> 0.3047619 | ... M16: =IF(ASSUMPTIONS!M5=0,"-",M12/ASSUMPTIONS!M5) -> 0.36
A17: Equity valuation / GDP (P/E-adjusted) | B17: Rising with FedCo suppression. The asset price inflation channel. Falls sharply in stress (Y10+). | C17: =IF(ASSUMPTIONS!C5=0,"-",C6/ASSUMPTIONS!C5) -> 4.3214286 | D17: =IF(ASSUMPTIONS!D5=0,"-",D6/ASSUMPTIONS!D5) -> 4.9337979 | E17: =IF(ASSUMPTIONS!E5=0,"-",E6/ASSUMPTIONS!E5) -> 5.6598639 | F17: =IF(ASSUMPTIONS!F5=0,"-",F6/ASSUMPTIONS!F5) -> 6.4900662 | G17: =IF(ASSUMPTIONS!G5=0,"-",G6/ASSUMPTIONS!G5) -> 5.4166667 | H17: =IF(ASSUMPTIONS!H5=0,"-",H6/ASSUMPTIONS!H5) -> 9.1 | I17: =IF(ASSUMPTIONS!I5=0,"-",I6/ASSUMPTIONS!I5) -> 11.103896 | J17: =IF(ASSUMPTIONS!J5=0,"-",J6/ASSUMPTIONS!J5) -> 10.057143 | ... M17: =IF(ASSUMPTIONS!M5=0,"-",M6/ASSUMPTIONS!M5) -> 6.6
A18: Output growth rate (TFP proxy) | B18: Real TFP gains. Positive. Key question: large enough to offset ManuCo contraction + FISIM inflation? | C18: - | D18: =IF(D14=0,"-",(D14-C14)/C14) -> 0.072727273 | E18: =IF(E14=0,"-",(E14-D14)/D14) -> 0.084745763 | F18: =IF(F14=0,"-",(F14-E14)/E14) -> 0.09375 | G18: =IF(G14=0,"-",(G14-F14)/F14) -> -0.071428571 | H18: =IF(H14=0,"-",(H14-G14)/G14) -> 0.2 | I18: =IF(I14=0,"-",(I14-H14)/H14) -> 0.15384615 | J18: =IF(J14=0,"-",(J14-I14)/I14) -> 0.1 | K18: =IF(K14=0,"-",(K14-J14)/J14) -> 0.11111111 | ... M18: =IF(M14=0,"-",(M14-L14)/L14) -> -0.06779661

Sheet FinServCo
A1: FinServCo | Pension Funds + Insurance | HedgeCo LP | FISIM Income
A2: Structural long-duration Treasury holder. LP in HedgeCo (basis trade). Long equities. In stress: yield spike hits all three simultaneously. FISIM spread income counted as GDP but not productive output.
A3: Account / Line Item | B3: Notes / Source | C3: Y0 | D3: Y1 | E3: Y2 | F3: Y3 | G3: Y4 | H3: Y5 | I3: Y6 | J3: Y7 | K3: Y8 | L3: Y9 | M3: Y10+ Stress
A4: ASSETS
A5: Long-duration Treasury portfolio ($B) [DYNAMIC: shrinks as HedgeCo scales] | B5: FinServCo is the explicit SELLER. TSY = TSY_Y0(60) - (HedgeCo_current - HedgeCo_Y0). Shrinks dollar-for-dollar as HedgeCo basis trade scales. Floor = 0 (cannot sell more than owned). Proceeds flow to equity portfolio (row 6). | C5: =MAX(0,60-MIN(60,MAX(0,(HedgeCo!C4-ASSUMPTIONS!C70)*ASSUMPTIONS!C84*2))) -> 60 | D5: =MAX(0,60-MIN(60,MAX(0,(HedgeCo!D4-ASSUMPTIONS!C70)*ASSUMPTIONS!C84*2))) -> 35.445 | E5: =MAX(0,60-MIN(60,MAX(0,(HedgeCo!E4-ASSUMPTIONS!C70)*ASSUMPTIONS!C84*2))) -> 0 | F5: =MAX(0,60-MIN(60,MAX(0,(HedgeCo!F4-ASSUMPTIONS!C70)*ASSUMPTIONS!C84*2))) -> 0 | G5: =MAX(0,60-MIN(60,MAX(0,(HedgeCo!G4-ASSUMPTIONS!C70)*ASSUMPTIONS!C84*2))) -> 0 | H5: =MAX(0,60-MIN(60,MAX(0,(HedgeCo!H4-ASSUMPTIONS!C70)*ASSUMPTIONS!C84*2))) -> 0 | I5: =MAX(0,60-MIN(60,MAX(0,(HedgeCo!I4-ASSUMPTIONS!C70)*ASSUMPTIONS!C84*2))) -> 0 | J5: =MAX(0,60-MIN(60,MAX(0,(HedgeCo!J4-ASSUMPTIONS!C70)*ASSUMPTIONS!C84*2))) -> 0 | K5: =MAX(0,60-MIN(60,MAX(0,(HedgeCo!K4-ASSUMPTIONS!C70)*ASSUMPTIONS!C84*2))) -> 0 | L5: =MAX(0,60-MIN(60,MAX(0,(HedgeCo!L4-ASSUMPTIONS!C70)*ASSUMPTIONS!C84*2))) -> 0 | M5: =MAX(0,60-MIN(60,MAX(0,(HedgeCo!M4-ASSUMPTIONS!C70)*ASSUMPTIONS!C84*2))) -> 0
A6: Equity portfolio ($B) [BASE + TSY sale proceeds reinvested as HedgeCo scales] | B6: Long equities. Base = 15% of ProdServiceCo equity (FedCo rate suppression). PLUS proceeds from Treasury sales as basis trade scales. This is the Part IV thesis link: FinServCo sells bonds → buys equity → ProdServiceCo valuation rises. | C6: =ProdServiceCo!C6*0.15+MAX(0,HedgeCo!C4-ASSUMPTIONS!C70) -> 181.5 | D6: =ProdServiceCo!D6*0.15+MAX(0,HedgeCo!D4-ASSUMPTIONS!C70) -> 236.955 | E6: =ProdServiceCo!E6*0.15+MAX(0,HedgeCo!E4-ASSUMPTIONS!C70) -> 315.5503 | F6: =ProdServiceCo!F6*0.15+MAX(0,HedgeCo!F4-ASSUMPTIONS!C70) -> 410.90748 | G6: =ProdServiceCo!G6*0.15+MAX(0,HedgeCo!G4-ASSUMPTIONS!C70) -> 396.17 | H6: =ProdServiceCo!H6*0.15+MAX(0,HedgeCo!H4-ASSUMPTIONS!C70) -> 634.56014 | I6: =ProdServiceCo!I6*0.15+MAX(0,HedgeCo!I4-ASSUMPTIONS!C70) -> 870.86861 | J6: =ProdServiceCo!J6*0.15+MAX(0,HedgeCo!J4-ASSUMPTIONS!C70) -> 968.84709 | K6: =ProdServiceCo!K6*0.15+MAX(0,HedgeCo!K4-ASSUMPTIONS!C70) -> 1168.9858 | L6: =ProdServiceCo!L6*0.15+MAX(0,HedgeCo!L4-ASSUMPTIONS!C70) -> 1344.4137 | M6: =ProdServiceCo!M6*0.15+MAX(0,HedgeCo!M4-ASSUMPTIONS!C70) -> 1239.5823
A7: LP stake in HedgeCo ($B) [SFC: Identity 17] | B7: Pension fund LP in basis trade vehicle. = HedgeCo equity * LP fraction (ASSUMPTIONS row 67). In stress: LP losses direct hit. | C7: =ASSUMPTIONS!C67*ASSUMPTIONS!C43 -> 3 | D7: =ASSUMPTIONS!D67*ASSUMPTIONS!D43 -> 3 | E7: =ASSUMPTIONS!E67*ASSUMPTIONS!E43 -> 3.2 | F7: =ASSUMPTIONS!F67*ASSUMPTIONS!F43 -> 3.2 | G7: =ASSUMPTIONS!G67*ASSUMPTIONS!G43 -> 3 | H7: =ASSUMPTIONS!H67*ASSUMPTIONS!H43 -> 3.5 | I7: =ASSUMPTIONS!I67*ASSUMPTIONS!I43 -> 3.8 | J7: =ASSUMPTIONS!J67*ASSUMPTIONS!J43 -> 4 | ... M7: =ASSUMPTIONS!M67*ASSUMPTIONS!M43 -> 4
A8: Repo receivable from AmeriBankCo ($B) [SFC: Identity 14] | B8: FedCo reserves -> AmeriBankCo -> repo -> FinServCo. Each FedCo absorption episode loads this. | C8: =AmeriBankCo!C5 -> 50 | D8: =AmeriBankCo!D5 -> 53 | E8: =AmeriBankCo!E5 -> 56.71 | F8: =AmeriBankCo!F5 -> 61.2468 | G8: =AmeriBankCo!G5 -> 76.5585 | H8: =AmeriBankCo!H5 -> 91.8702 | I8: =AmeriBankCo!I5 -> 105.65073 | J8: =AmeriBankCo!J5 -> 116.2158 | ... M8: =AmeriBankCo!M5 -> 151.55703
A9: Private credit loans to ProdServiceCo ($B) [ILLIQUID | SFC: = ProdServiceCo!priv_credit_debt] | B9: 5-7yr lockup. Not in TIC, not in H.8. Funded via AmeriBankCo repo. SFC: mirror identity with ProdServiceCo PC debt. | C9: =ASSUMPTIONS!C75 -> 20 | D9: =C9*(1+ASSUMPTIONS!D76) -> 22 | E9: =D9*(1+ASSUMPTIONS!E76) -> 25.08 | F9: =E9*(1+ASSUMPTIONS!F76) -> 28.0896 | G9: =F9*(1+ASSUMPTIONS!G76) -> 32.864832 | H9: =G9*(1+ASSUMPTIONS!H76) -> 37.465908 | I9: =H9*(1+ASSUMPTIONS!I76) -> 42.711136 | J9: =I9*(1+ASSUMPTIONS!J76) -> 47.409361 | K9: =J9*(1+ASSUMPTIONS!K76) -> 52.150297 | ... M9: =L9*(1+ASSUMPTIONS!M76) -> 52.202447
